TypeError in line 6 of /home/xinyut/workflows/16s-pipeline/microbiome.smk:
data type not understood
  File "/home/xinyut/workflows/16s-pipeline/microbiome.smk", line 6, in <module>
  File "/home/xinyut/miniconda3/lib/python3.7/site-packages/pandas/io/parsers.py", line 685, in parser_f
  File "/home/xinyut/miniconda3/lib/python3.7/site-packages/pandas/io/parsers.py", line 457, in _read
  File "/home/xinyut/miniconda3/lib/python3.7/site-packages/pandas/io/parsers.py", line 895, in __init__
  File "/home/xinyut/miniconda3/lib/python3.7/site-packages/pandas/io/parsers.py", line 1135, in _make_engine
  File "/home/xinyut/miniconda3/lib/python3.7/site-packages/pandas/io/parsers.py", line 1917, in __init__
  File "pandas/_libs/parsers.pyx", line 493, in pandas._libs.parsers.TextReader.__cinit__
  File "/home/xinyut/miniconda3/lib/python3.7/site-packages/pandas/core/dtypes/common.py", line 2054, in pandas_dtype
